Workbook

Sheet Dashboard
A1: Inventory Management Dashboard
A2: Mobile accessories store - 1 year (Jan-Dec)
B4: Month: | C4: Jan | E4: Category: | F4: Cases | H4: Product: | I4: All
A6: Note: Cost Metrics, Stock/Reorder, Sales Analysis and Health Check below respond to these filters. Overall totals (Layer 1) never change.
A8: Layer 1 - Overall Totals (always unfiltered)
A9: Total Stock Available (Units) | F9: Total Cost of Inventory (Rs)
A10: =SUM('Product Summary'!$T$2:$T$51) -> 16933 | F10: =SUM('Product Summary'!$E$2:$E$51) -> 34893890
A12: Layer 2 - Cost Metrics (filtered)
A14: Ordering Cost / Order (Rs) | D14: Value at Cost (Filtered, Rs) | H14: Overstock / Slow-Moving Value (Filtered, Rs)
A15: =AVERAGE('Item Master'!$G$2:$G$51) -> 500 | D15: =SUMPRODUCT((Calculations!$D$2:$D$601=IF($C$4="All",Calculations!$D$2:$D$601,$C$4))*(Calculations!$C$2:$C$601=IF($F$4="All",Calculations!$C$2:$C$601,$F$4))*(Calculations!$B$2:$B$601=IF($I$4="All",Calculations!$B$2:$B$601,$I$4))*(Calculations!$L$2:$L$601)) -> 121950 | H15: {=SUMPRODUCT((Calculations!$D$2:$D$601=IF($C$4="All","Dec",$C$4))*(Calculations!$C$2:$C$601=IF($F$4="All",Calculations!$C$2:$C$601,$F$4))*(Calculations!$B$2:$B$601=IF($I$4="All",Calculations!$B$2:$B$601,$I$4))*(Calculations!$S$2:$S$601="OVERSTOCK")*(Calculations!$J$2:$J$601)*(Calculations!$K$2:$K$601))} -> 0
A17: Layer 3 - Stock Availability & Reorder Status (filtered)
A18: Current Stock (Units) | D18: Reorder Level (Units) | G18: Safety Stock (Units) | I18: Avg Days Until Reorder (ALARM if low)
A19: =SUMPRODUCT((Calculations!$D$2:$D$601=IF($C$4="All","Dec",$C$4))*(Calculations!$C$2:$C$601=IF($F$4="All",Calculations!$C$2:$C$601,$F$4))*(Calculations!$B$2:$B$601=IF($I$4="All",Calculations!$B$2:$B$601,$I$4))*(Calculations!$J$2:$J$601)) -> 1414 | D19: =SUMPRODUCT((Calculations!$D$2:$D$601=IF($C$4="All","Dec",$C$4))*(Calculations!$C$2:$C$601=IF($F$4="All",Calculations!$C$2:$C$601,$F$4))*(Calculations!$B$2:$B$601=IF($I$4="All",Calculations!$B$2:$B$601,$I$4))*(Calculations!$P$2:$P$601)) -> 130.42998 | G19: =SUMPRODUCT((Calculations!$D$2:$D$601=IF($C$4="All","Dec",$C$4))*(Calculations!$C$2:$C$601=IF($F$4="All",Calculations!$C$2:$C$601,$F$4))*(Calculations!$B$2:$B$601=IF($I$4="All",Calculations!$B$2:$B$601,$I$4))*(Calculations!$O$2:$O$601)) -> 46.188889 | I19: =IFERROR(SUMPRODUCT((Calculations!$D$2:$D$601=IF($C$4="All","Dec",$C$4))*(Calculations!$C$2:$C$601=IF($F$4="All",Calculations!$C$2:$C$601,$F$4))*(Calculations!$B$2:$B$601=IF($I$4="All",Calculations!$B$2:$B$601,$I$4))*(Calculations!$R$2:$R$601))/SUMPRODUCT((Calculations!$D$2:$D$601=IF($C$4="All","Dec",$C$4))*(Calculations!$C$2:$C$601=IF($F$4="All",Calculations!$C$2:$C$601,$F$4))*(Calculations!$B$2:$B$601=IF($I$4="All",Calculations!$B$2:$B$601,$I$4))*1),0) -> 82.797911
A21: Products Needing Reorder Now (count, filtered)
A22: =SUMPRODUCT((Calculations!$D$2:$D$601=IF($C$4="All","Dec",$C$4))*(Calculations!$C$2:$C$601=IF($F$4="All",Calculations!$C$2:$C$601,$F$4))*(Calculations!$B$2:$B$601=IF($I$4="All",Calculations!$B$2:$B$601,$I$4))*(Calculations!$S$2:$S$601="REORDER NOW")) -> 0 | E22: Tip: open the Calculations sheet and use the column filter arrows for the full row-by-row list.
A24: Layer 4 - Sales Analysis (filtered, by month)
A25: Month | B25: Units Sold | C25: Cost (Rs) | E25: Category | F25: Cost Contribution (Rs)
A26: Jan | B26: =SUMPRODUCT((Calculations!$D$2:$D$601="Jan")*(Calculations!$C$2:$C$601=IF($F$4="All",Calculations!$C$2:$C$601,$F$4))*(Calculations!$B$2:$B$601=IF($I$4="All",Calculations!$B$2:$B$601,$I$4))*(Calculations!$H$2:$H$601)) -> 477 | C26: =SUMPRODUCT((Calculations!$D$2:$D$601="Jan")*(Calculations!$C$2:$C$601=IF($F$4="All",Calculations!$C$2:$C$601,$F$4))*(Calculations!$B$2:$B$601=IF($I$4="All",Calculations!$B$2:$B$601,$I$4))*(Calculations!$L$2:$L$601)) -> 121950 | E26: Accessories | F26: =SUMPRODUCT((Calculations!$D$2:$D$601=IF($C$4="All",Calculations!$D$2:$D$601,$C$4))*(Calculations!$C$2:$C$601="Accessories")*(Calculations!$B$2:$B$601=IF($I$4="All",Calculations!$B$2:$B$601,$I$4))*(Calculations!$L$2:$L$601)) -> 42100
A27: Feb | B27: =SUMPRODUCT((Calculations!$D$2:$D$601="Feb")*(Calculations!$C$2:$C$601=IF($F$4="All",Calculations!$C$2:$C$601,$F$4))*(Calculations!$B$2:$B$601=IF($I$4="All",Calculations!$B$2:$B$601,$I$4))*(Calculations!$H$2:$H$601)) -> 465 | C27: =SUMPRODUCT((Calculations!$D$2:$D$601="Feb")*(Calculations!$C$2:$C$601=IF($F$4="All",Calculations!$C$2:$C$601,$F$4))*(Calculations!$B$2:$B$601=IF($I$4="All",Calculations!$B$2:$B$601,$I$4))*(Calculations!$L$2:$L$601)) -> 121250 | E27: Audio | F27: =SUMPRODUCT((Calculations!$D$2:$D$601=IF($C$4="All",Calculations!$D$2:$D$601,$C$4))*(Calculations!$C$2:$C$601="Audio")*(Calculations!$B$2:$B$601=IF($I$4="All",Calculations!$B$2:$B$601,$I$4))*(Calculations!$L$2:$L$601)) -> 1531100
A28: Mar | B28: =SUMPRODUCT((Calculations!$D$2:$D$601="Mar")*(Calculations!$C$2:$C$601=IF($F$4="All",Calculations!$C$2:$C$601,$F$4))*(Calculations!$B$2:$B$601=IF($I$4="All",Calculations!$B$2:$B$601,$I$4))*(Calculations!$H$2:$H$601)) -> 458 | C28: =SUMPRODUCT((Calculations!$D$2:$D$601="Mar")*(Calculations!$C$2:$C$601=IF($F$4="All",Calculations!$C$2:$C$601,$F$4))*(Calculations!$B$2:$B$601=IF($I$4="All",Calculations!$B$2:$B$601,$I$4))*(Calculations!$L$2:$L$601)) -> 118200 | E28: Cables | F28: =SUMPRODUCT((Calculations!$D$2:$D$601=IF($C$4="All",Calculations!$D$2:$D$601,$C$4))*(Calculations!$C$2:$C$601="Cables")*(Calculations!$B$2:$B$601=IF($I$4="All",Calculations!$B$2:$B$601,$I$4))*(Calculations!$L$2:$L$601)) -> 109090
A29: Apr | B29: =SUMPRODUCT((Calculations!$D$2:$D$601="Apr")*(Calculations!$C$2:$C$601=IF($F$4="All",Calculations!$C$2:$C$601,$F$4))*(Calculations!$B$2:$B$601=IF($I$4="All",Calculations!$B$2:$B$601,$I$4))*(Calculations!$H$2:$H$601)) -> 447 | C29: =SUMPRODUCT((Calculations!$D$2:$D$601="Apr")*(Calculations!$C$2:$C$601=IF($F$4="All",Calculations!$C$2:$C$601,$F$4))*(Calculations!$B$2:$B$601=IF($I$4="All",Calculations!$B$2:$B$601,$I$4))*(Calculations!$L$2:$L$601)) -> 117050 | E29: Cases | F29: =SUMPRODUCT((Calculations!$D$2:$D$601=IF($C$4="All",Calculations!$D$2:$D$601,$C$4))*(Calculations!$C$2:$C$601="Cases")*(Calculations!$B$2:$B$601=IF($I$4="All",Calculations!$B$2:$B$601,$I$4))*(Calculations!$L$2:$L$601)) -> 121950
A30: May | B30: =SUMPRODUCT((Calculations!$D$2:$D$601="May")*(Calculations!$C$2:$C$601=IF($F$4="All",Calculations!$C$2:$C$601,$F$4))*(Calculations!$B$2:$B$601=IF($I$4="All",Calculations!$B$2:$B$601,$I$4))*(Calculations!$H$2:$H$601)) -> 434 | C30: =SUMPRODUCT((Calculations!$D$2:$D$601="May")*(Calculations!$C$2:$C$601=IF($F$4="All",Calculations!$C$2:$C$601,$F$4))*(Calculations!$B$2:$B$601=IF($I$4="All",Calculations!$B$2:$B$601,$I$4))*(Calculations!$L$2:$L$601)) -> 116400 | E30: Chargers | F30: =SUMPRODUCT((Calculations!$D$2:$D$601=IF($C$4="All",Calculations!$D$2:$D$601,$C$4))*(Calculations!$C$2:$C$601="Chargers")*(Calculations!$B$2:$B$601=IF($I$4="All",Calculations!$B$2:$B$601,$I$4))*(Calculations!$L$2:$L$601)) -> 209950
A31: Jun | B31: =SUMPRODUCT((Calculations!$D$2:$D$601="Jun")*(Calculations!$C$2:$C$601=IF($F$4="All",Calculations!$C$2:$C$601,$F$4))*(Calculations!$B$2:$B$601=IF($I$4="All",Calculations!$B$2:$B$601,$I$4))*(Calculations!$H$2:$H$601)) -> 451 | C31: =SUMPRODUCT((Calculations!$D$2:$D$601="Jun")*(Calculations!$C$2:$C$601=IF($F$4="All",Calculations!$C$2:$C$601,$F$4))*(Calculations!$B$2:$B$601=IF($I$4="All",Calculations!$B$2:$B$601,$I$4))*(Calculations!$L$2:$L$601)) -> 120950 | E31: Gaming | F31: =SUMPRODUCT((Calculations!$D$2:$D$601=IF($C$4="All",Calculations!$D$2:$D$601,$C$4))*(Calculations!$C$2:$C$601="Gaming")*(Calculations!$B$2:$B$601=IF($I$4="All",Calculations!$B$2:$B$601,$I$4))*(Calculations!$L$2:$L$601)) -> 44000
A32: Jul | B32: =SUMPRODUCT((Calculations!$D$2:$D$601="Jul")*(Calculations!$C$2:$C$601=IF($F$4="All",Calculations!$C$2:$C$601,$F$4))*(Calculations!$B$2:$B$601=IF($I$4="All",Calculations!$B$2:$B$601,$I$4))*(Calculations!$H$2:$H$601)) -> 482 | C32: =SUMPRODUCT((Calculations!$D$2:$D$601="Jul")*(Calculations!$C$2:$C$601=IF($F$4="All",Calculations!$C$2:$C$601,$F$4))*(Calculations!$B$2:$B$601=IF($I$4="All",Calculations!$B$2:$B$601,$I$4))*(Calculations!$L$2:$L$601)) -> 122500 | E32: Peripherals | F32: =SUMPRODUCT((Calculations!$D$2:$D$601=IF($C$4="All",Calculations!$D$2:$D$601,$C$4))*(Calculations!$C$2:$C$601="Peripherals")*(Calculations!$B$2:$B$601=IF($I$4="All",Calculations!$B$2:$B$601,$I$4))*(Calculations!$L$2:$L$601)) -> 79600
A33: Aug | B33: =SUMPRODUCT((Calculations!$D$2:$D$601="Aug")*(Calculations!$C$2:$C$601=IF($F$4="All",Calculations!$C$2:$C$601,$F$4))*(Calculations!$B$2:$B$601=IF($I$4="All",Calculations!$B$2:$B$601,$I$4))*(Calculations!$H$2:$H$601)) -> 433 | C33: =SUMPRODUCT((Calculations!$D$2:$D$601="Aug")*(Calculations!$C$2:$C$601=IF($F$4="All",Calculations!$C$2:$C$601,$F$4))*(Calculations!$B$2:$B$601=IF($I$4="All",Calculations!$B$2:$B$601,$I$4))*(Calculations!$L$2:$L$601)) -> 116250 | E33: Power Banks | F33: =SUMPRODUCT((Calculations!$D$2:$D$601=IF($C$4="All",Calculations!$D$2:$D$601,$C$4))*(Calculations!$C$2:$C$601="Power Banks")*(Calculations!$B$2:$B$601=IF($I$4="All",Calculations!$B$2:$B$601,$I$4))*(Calculations!$L$2:$L$601)) -> 260400
A34: Sep | B34: =SUMPRODUCT((Calculations!$D$2:$D$601="Sep")*(Calculations!$C$2:$C$601=IF($F$4="All",Calculations!$C$2:$C$601,$F$4))*(Calculations!$B$2:$B$601=IF($I$4="All",Calculations!$B$2:$B$601,$I$4))*(Calculations!$H$2:$H$601)) -> 470 | C34: =SUMPRODUCT((Calculations!$D$2:$D$601="Sep")*(Calculations!$C$2:$C$601=IF($F$4="All",Calculations!$C$2:$C$601,$F$4))*(Calculations!$B$2:$B$601=IF($I$4="All",Calculations!$B$2:$B$601,$I$4))*(Calculations!$L$2:$L$601)) -> 123000 | E34: Screen Protection | F34: =SUMPRODUCT((Calculations!$D$2:$D$601=IF($C$4="All",Calculations!$D$2:$D$601,$C$4))*(Calculations!$C$2:$C$601="Screen Protection")*(Calculations!$B$2:$B$601=IF($I$4="All",Calculations!$B$2:$B$601,$I$4))*(Calculations!$L$2:$L$601)) -> 27130
A35: Oct | B35: =SUMPRODUCT((Calculations!$D$2:$D$601="Oct")*(Calculations!$C$2:$C$601=IF($F$4="All",Calculations!$C$2:$C$601,$F$4))*(Calculations!$B$2:$B$601=IF($I$4="All",Calculations!$B$2:$B$601,$I$4))*(Calculations!$H$2:$H$601)) -> 735 | C35: =SUMPRODUCT((Calculations!$D$2:$D$601="Oct")*(Calculations!$C$2:$C$601=IF($F$4="All",Calculations!$C$2:$C$601,$F$4))*(Calculations!$B$2:$B$601=IF($I$4="All",Calculations!$B$2:$B$601,$I$4))*(Calculations!$L$2:$L$601)) -> 193950 | E35: Storage | F35: =SUMPRODUCT((Calculations!$D$2:$D$601=IF($C$4="All",Calculations!$D$2:$D$601,$C$4))*(Calculations!$C$2:$C$601="Storage")*(Calculations!$B$2:$B$601=IF($I$4="All",Calculations!$B$2:$B$601,$I$4))*(Calculations!$L$2:$L$601)) -> 156650
A36: Nov | B36: =SUMPRODUCT((Calculations!$D$2:$D$601="Nov")*(Calculations!$C$2:$C$601=IF($F$4="All",Calculations!$C$2:$C$601,$F$4))*(Calculations!$B$2:$B$601=IF($I$4="All",Calculations!$B$2:$B$601,$I$4))*(Calculations!$H$2:$H$601)) -> 520 | C36: =SUMPRODUCT((Calculations!$D$2:$D$601="Nov")*(Calculations!$C$2:$C$601=IF($F$4="All",Calculations!$C$2:$C$601,$F$4))*(Calculations!$B$2:$B$601=IF($I$4="All",Calculations!$B$2:$B$601,$I$4))*(Calculations!$L$2:$L$601)) -> 135500 | E36: Wearable Accessories | F36: =SUMPRODUCT((Calculations!$D$2:$D$601=IF($C$4="All",Calculations!$D$2:$D$601,$C$4))*(Calculations!$C$2:$C$601="Wearable Accessories")*(Calculations!$B$2:$B$601=IF($I$4="All",Calculations!$B$2:$B$601,$I$4))*(Calculations!$L$2:$L$601)) -> 23370
A37: Dec | B37: =SUMPRODUCT((Calculations!$D$2:$D$601="Dec")*(Calculations!$C$2:$C$601=IF($F$4="All",Calculations!$C$2:$C$601,$F$4))*(Calculations!$B$2:$B$601=IF($I$4="All",Calculations!$B$2:$B$601,$I$4))*(Calculations!$H$2:$H$601)) -> 439 | C37: =SUMPRODUCT((Calculations!$D$2:$D$601="Dec")*(Calculations!$C$2:$C$601=IF($F$4="All",Calculations!$C$2:$C$601,$F$4))*(Calculations!$B$2:$B$601=IF($I$4="All",Calculations!$B$2:$B$601,$I$4))*(Calculations!$L$2:$L$601)) -> 113550 | E37: Wearables | F37: =SUMPRODUCT((Calculations!$D$2:$D$601=IF($C$4="All",Calculations!$D$2:$D$601,$C$4))*(Calculations!$C$2:$C$601="Wearables")*(Calculations!$B$2:$B$601=IF($I$4="All",Calculations!$B$2:$B$601,$I$4))*(Calculations!$L$2:$L$601)) -> 122400
A56: Layer 5 - Health Check: Avg Sales/Day, Turnover Ratio, ABC Category (filtered)
A57: Avg Sales per Day (Units) | E57: Inventory Turnover Ratio | I57: ABC Class
A58: =IF($I$4="All",IFERROR(SUMPRODUCT(('Product Summary'!$C$2:$C$51=IF($F$4="All",'Product Summary'!$C$2:$C$51,$F$4))*('Product Summary'!$D$2:$D$51))/365,0),INDEX('Product Summary'!$F$2:$F$51,MATCH($I$4,'Product Summary'!$B$2:$B$51,0))) -> 15.920548 | E58: =IF($I$4="All",IFERROR(SUMPRODUCT(('Product Summary'!$C$2:$C$51=IF($F$4="All",'Product Summary'!$C$2:$C$51,$F$4))*('Product Summary'!$E$2:$E$51))/SUMPRODUCT(('Product Summary'!$C$2:$C$51=IF($F$4="All",'Product Summary'!$C$2:$C$51,$F$4))*('Product Summary'!$V$2:$V$51)),0),INDEX('Product Summary'!$W$2:$W$51,MATCH($I$4,'Product Summary'!$B$2:$B$51,0))) -> 3.1815661 | I58: =IF($I$4="All","See % split below",INDEX('Product Summary'!$AA$2:$AA$51,MATCH($I$4,'Product Summary'!$B$2:$B$51,0))) -> See % split below
A60: ABC value split (% of total value in filtered scope) - shown when Product = All
A61: Class A - % of Value | D61: Class B - % of Value | G61: Class C - % of Value
A62: =IFERROR(SUMPRODUCT(('Product Summary'!$C$2:$C$51=IF($F$4="All",'Product Summary'!$C$2:$C$51,$F$4))*('Product Summary'!$AA$2:$AA$51="A")*('Product Summary'!$Y$2:$Y$51))/SUMPRODUCT(('Product Summary'!$C$2:$C$51=IF($F$4="All",'Product Summary'!$C$2:$C$51,$F$4))*('Product Summary'!$Y$2:$Y$51)),0) -> 0 | D62: =IFERROR(SUMPRODUCT(('Product Summary'!$C$2:$C$51=IF($F$4="All",'Product Summary'!$C$2:$C$51,$F$4))*('Product Summary'!$AA$2:$AA$51="B")*('Product Summary'!$Y$2:$Y$51))/SUMPRODUCT(('Product Summary'!$C$2:$C$51=IF($F$4="All",'Product Summary'!$C$2:$C$51,$F$4))*('Product Summary'!$Y$2:$Y$51)),0) -> 1 | G62: =IFERROR(SUMPRODUCT(('Product Summary'!$C$2:$C$51=IF($F$4="All",'Product Summary'!$C$2:$C$51,$F$4))*('Product Summary'!$AA$2:$AA$51="C")*('Product Summary'!$Y$2:$Y$51))/SUMPRODUCT(('Product Summary'!$C$2:$C$51=IF($F$4="All",'Product Summary'!$C$2:$C$51,$F$4))*('Product Summary'!$Y$2:$Y$51)),0) -> 0
A64: Reviewing frequency policy: Class A = Weekly | Class B = Monthly | Class C = Quarterly

Sheet Item Master
A1: Product ID | B1: Product Name | C1: Category | D1: Supplier | E1: Lead Time (Days) | F1: Cost per Unit (Rs) | G1: Ordering Cost per Order (Rs) | H1: Holding Cost per Unit per Year (Rs)
A2: SKU001 | B2: Wireless Earbuds Pro | C2: Audio | D2: Shenzhen Tech Traders | E2: 5 | F2: 1800 | G2: 500 | H2: 360
A3: SKU002 | B3: Bluetooth Speaker Mini | C3: Audio | D3: Metro Electronics Wholesale | E3: 3 | F3: 1200 | G3: 500 | H3: 240
A4: SKU003 | B4: Bluetooth Speaker XL | C4: Audio | D4: Shenzhen Tech Traders | E4: 5 | F4: 2200 | G4: 500 | H4: 440
A5: SKU004 | B5: Wired Earphones Basic | C5: Audio | D5: Coastal Import Export | E5: 14 | F5: 150 | G5: 500 | H5: 30
A6: SKU005 | B6: Noise Cancelling Headphones | C6: Audio | D6: Global Accessories Co. | E6: 7 | F6: 3500 | G6: 500 | H6: 700
A7: SKU006 | B7: USB-C Charging Cable 1m | C7: Cables | D7: Shenzhen Tech Traders | E7: 5 | F7: 90 | G7: 500 | H7: 18
A8: SKU007 | B8: USB-C Charging Cable 2m | C8: Cables | D8: Shenzhen Tech Traders | E8: 5 | F8: 130 | G8: 500 | H8: 26
A9: SKU008 | B9: Lightning Cable 1m | C9: Cables | D9: Metro Electronics Wholesale | E9: 3 | F9: 150 | G9: 500 | H9: 30
A10: SKU009 | B10: Micro USB Cable | C10: Cables | D10: Coastal Import Export | E10: 14 | F10: 60 | G10: 500 | H10: 12
A11: SKU010 | B11: HDMI Cable 2m | C11: Cables | D11: Global Accessories Co. | E11: 7 | F11: 200 | G11: 500 | H11: 40
A12: SKU011 | B12: 20W Fast Charger Adapter | C12: Chargers | D12: Prime Gadget Distributors | E12: 10 | F12: 400 | G12: 500 | H12: 80
A13: SKU012 | B13: 65W GaN Charger | C13: Chargers | D13: Shenzhen Tech Traders | E13: 5 | F13: 1100 | G13: 500 | H13: 220
... A51: SKU050 | B51: Anti-Theft Phone Pouch | C51: Accessories | D51: Global Accessories Co. | E51: 7 | F51: 180 | G51: 500 | H51: 36

Sheet Stock Inflow
A1: Product ID | B1: Product Name | C1: Product Category | D1: Month | E1: Returns from Customer | F1: Purchase | G1: Opening Stock
A2: SKU001 | B2: Wireless Earbuds Pro | C2: Audio | D2: Jan | E2: 2 | F2: 126 | G2: 220
A3: SKU001 | B3: Wireless Earbuds Pro | C3: Audio | D3: Feb | E3: 2 | F3: 165 | G3: 213
A4: SKU001 | B4: Wireless Earbuds Pro | C4: Audio | D4: Mar | E4: 4 | F4: 151 | G4: 235
A5: SKU001 | B5: Wireless Earbuds Pro | C5: Audio | D5: Apr | E5: 4 | F5: 162 | G5: 255
A6: SKU001 | B6: Wireless Earbuds Pro | C6: Audio | D6: May | E6: 2 | F6: 191 | G6: 268
A7: SKU001 | B7: Wireless Earbuds Pro | C7: Audio | D7: Jun | E7: 4 | F7: 131 | G7: 300
A8: SKU001 | B8: Wireless Earbuds Pro | C8: Audio | D8: Jul | E8: 3 | F8: 144 | G8: 302
A9: SKU001 | B9: Wireless Earbuds Pro | C9: Audio | D9: Aug | E9: 2 | F9: 133 | G9: 310
A10: SKU001 | B10: Wireless Earbuds Pro | C10: Audio | D10: Sep | E10: 4 | F10: 127 | G10: 318
A11: SKU001 | B11: Wireless Earbuds Pro | C11: Audio | D11: Oct | E11: 3 | F11: 214 | G11: 321
A12: SKU001 | B12: Wireless Earbuds Pro | C12: Audio | D12: Nov | E12: 6 | F12: 230 | G12: 315
A13: SKU001 | B13: Wireless Earbuds Pro | C13: Audio | D13: Dec | E13: 5 | F13: 149 | G13: 367
... A601: SKU050 | B601: Anti-Theft Phone Pouch | C601: Accessories | D601: Dec | E601: 1 | F601: 20 | G601: 418

Sheet Stock Outflow
A1: Product ID | B1: Product Name | C1: Product Category | D1: Month | E1: Return to Supplier | F1: Sales
A2: SKU001 | B2: Wireless Earbuds Pro | C2: Audio | D2: Jan | E2: 3 | F2: 132
A3: SKU001 | B3: Wireless Earbuds Pro | C3: Audio | D3: Feb | E3: 0 | F3: 145
A4: SKU001 | B4: Wireless Earbuds Pro | C4: Audio | D4: Mar | E4: 3 | F4: 132
A5: SKU001 | B5: Wireless Earbuds Pro | C5: Audio | D5: Apr | E5: 1 | F5: 152
A6: SKU001 | B6: Wireless Earbuds Pro | C6: Audio | D6: May | E6: 2 | F6: 159
A7: SKU001 | B7: Wireless Earbuds Pro | C7: Audio | D7: Jun | E7: 0 | F7: 133
A8: SKU001 | B8: Wireless Earbuds Pro | C8: Audio | D8: Jul | E8: 1 | F8: 138
A9: SKU001 | B9: Wireless Earbuds Pro | C9: Audio | D9: Aug | E9: 4 | F9: 123
A10: SKU001 | B10: Wireless Earbuds Pro | C10: Audio | D10: Sep | E10: 3 | F10: 125
A11: SKU001 | B11: Wireless Earbuds Pro | C11: Audio | D11: Oct | E11: 4 | F11: 219
A12: SKU001 | B12: Wireless Earbuds Pro | C12: Audio | D12: Nov | E12: 6 | F12: 178
A13: SKU001 | B13: Wireless Earbuds Pro | C13: Audio | D13: Dec | E13: 1 | F13: 138
... A601: SKU050 | B601: Anti-Theft Phone Pouch | C601: Accessories | D601: Dec | E601: 1 | F601: 18

Sheet Sales
A1: Month | B1: Product ID | C1: Product Name | D1: Category | E1: Units Sold | F1: Cost per Unit (Rs)
A2: Jan | B2: SKU001 | C2: Wireless Earbuds Pro | D2: Audio | E2: 132 | F2: 1800
A3: Feb | B3: SKU001 | C3: Wireless Earbuds Pro | D3: Audio | E3: 145 | F3: 1800
A4: Mar | B4: SKU001 | C4: Wireless Earbuds Pro | D4: Audio | E4: 132 | F4: 1800
A5: Apr | B5: SKU001 | C5: Wireless Earbuds Pro | D5: Audio | E5: 152 | F5: 1800
A6: May | B6: SKU001 | C6: Wireless Earbuds Pro | D6: Audio | E6: 159 | F6: 1800
A7: Jun | B7: SKU001 | C7: Wireless Earbuds Pro | D7: Audio | E7: 133 | F7: 1800
A8: Jul | B8: SKU001 | C8: Wireless Earbuds Pro | D8: Audio | E8: 138 | F8: 1800
A9: Aug | B9: SKU001 | C9: Wireless Earbuds Pro | D9: Audio | E9: 123 | F9: 1800
A10: Sep | B10: SKU001 | C10: Wireless Earbuds Pro | D10: Audio | E10: 125 | F10: 1800
A11: Oct | B11: SKU001 | C11: Wireless Earbuds Pro | D11: Audio | E11: 219 | F11: 1800
A12: Nov | B12: SKU001 | C12: Wireless Earbuds Pro | D12: Audio | E12: 178 | F12: 1800
A13: Dec | B13: SKU001 | C13: Wireless Earbuds Pro | D13: Audio | E13: 138 | F13: 1800
... A601: Dec | B601: SKU050 | C601: Anti-Theft Phone Pouch | D601: Accessories | E601: 18 | F601: 180

Sheet Calculations
A1: Product ID | B1: Product Name | C1: Category | D1: Month | E1: Opening Stock | F1: Purchase | G1: Customer Returns | H1: Sales | I1: Return to Supplier | J1: Closing Stock | K1: Cost per Unit (Rs) | L1: Monthly Cost (Rs) | M1: Avg Daily Usage (Monthly) | N1: Lead Time (Days) | O1: Safety Stock | P1: Reorder Level | Q1: Days of Stock Remaining | R1: Days Until Reorder | S1: Stock Status
A2: SKU001 | B2: Wireless Earbuds Pro | C2: Audio | D2: Jan | E2: =SUMIFS('Stock Inflow'!$G$2:$G$601,'Stock Inflow'!$A$2:$A$601,$A2,'Stock Inflow'!$D$2:$D$601,$D2) -> 220 | F2: =SUMIFS('Stock Inflow'!$F$2:$F$601,'Stock Inflow'!$A$2:$A$601,$A2,'Stock Inflow'!$D$2:$D$601,$D2) -> 126 | G2: =SUMIFS('Stock Inflow'!$E$2:$E$601,'Stock Inflow'!$A$2:$A$601,$A2,'Stock Inflow'!$D$2:$D$601,$D2) -> 2 | H2: =SUMIFS('Stock Outflow'!$F$2:$F$601,'Stock Outflow'!$A$2:$A$601,$A2,'Stock Outflow'!$D$2:$D$601,$D2) -> 132 | I2: =SUMIFS('Stock Outflow'!$E$2:$E$601,'Stock Outflow'!$A$2:$A$601,$A2,'Stock Outflow'!$D$2:$D$601,$D2) -> 3 | J2: =E2+F2+G2-H2-I2 -> 213 | K2: =INDEX('Item Master'!$F$2:$F$51,MATCH($A2,'Item Master'!$A$2:$A$51,0)) -> 1800 | L2: =H2*K2 -> 237600 | M2: =H2/30 -> 4.4 | N2: =INDEX('Item Master'!$E$2:$E$51,MATCH($A2,'Item Master'!$A$2:$A$51,0)) -> 5 | O2: =INDEX('Product Summary'!$L$2:$L$51,MATCH($A2,'Product Summary'!$A$2:$A$51,0)) -> 11.861111 | P2: =INDEX('Product Summary'!$M$2:$M$51,MATCH($A2,'Product Summary'!$A$2:$A$51,0)) -> 36.162481 | Q2: =IF(M2=0,"",J2/M2) -> 48.409091 | R2: =IF(M2=0,"",IF(J2<=P2,0,(J2-P2)/M2)) -> 40.190345 | S2: =IF(J2<=P2,"REORDER NOW",IF(IFERROR(Q2,0)>150,"OVERSTOCK","HEALTHY")) -> HEALTHY
A3: SKU001 | B3: Wireless Earbuds Pro | C3: Audio | D3: Feb | E3: =SUMIFS('Stock Inflow'!$G$2:$G$601,'Stock Inflow'!$A$2:$A$601,$A3,'Stock Inflow'!$D$2:$D$601,$D3) -> 213 | F3: =SUMIFS('Stock Inflow'!$F$2:$F$601,'Stock Inflow'!$A$2:$A$601,$A3,'Stock Inflow'!$D$2:$D$601,$D3) -> 165 | G3: =SUMIFS('Stock Inflow'!$E$2:$E$601,'Stock Inflow'!$A$2:$A$601,$A3,'Stock Inflow'!$D$2:$D$601,$D3) -> 2 | H3: =SUMIFS('Stock Outflow'!$F$2:$F$601,'Stock Outflow'!$A$2:$A$601,$A3,'Stock Outflow'!$D$2:$D$601,$D3) -> 145 | I3: =SUMIFS('Stock Outflow'!$E$2:$E$601,'Stock Outflow'!$A$2:$A$601,$A3,'Stock Outflow'!$D$2:$D$601,$D3) -> 0 | J3: =E3+F3+G3-H3-I3 -> 235 | K3: =INDEX('Item Master'!$F$2:$F$51,MATCH($A3,'Item Master'!$A$2:$A$51,0)) -> 1800 | L3: =H3*K3 -> 261000 | M3: =H3/30 -> 4.8333333 | N3: =INDEX('Item Master'!$E$2:$E$51,MATCH($A3,'Item Master'!$A$2:$A$51,0)) -> 5 | O3: =INDEX('Product Summary'!$L$2:$L$51,MATCH($A3,'Product Summary'!$A$2:$A$51,0)) -> 11.861111 | P3: =INDEX('Product Summary'!$M$2:$M$51,MATCH($A3,'Product Summary'!$A$2:$A$51,0)) -> 36.162481 | Q3: =IF(M3=0,"",J3/M3) -> 48.62069 | R3: =IF(M3=0,"",IF(J3<=P3,0,(J3-P3)/M3)) -> 41.138797 | S3: =IF(J3<=P3,"REORDER NOW",IF(IFERROR(Q3,0)>150,"OVERSTOCK","HEALTHY")) -> HEALTHY
A4: SKU001 | B4: Wireless Earbuds Pro | C4: Audio | D4: Mar | E4: =SUMIFS('Stock Inflow'!$G$2:$G$601,'Stock Inflow'!$A$2:$A$601,$A4,'Stock Inflow'!$D$2:$D$601,$D4) -> 235 | F4: =SUMIFS('Stock Inflow'!$F$2:$F$601,'Stock Inflow'!$A$2:$A$601,$A4,'Stock Inflow'!$D$2:$D$601,$D4) -> 151 | G4: =SUMIFS('Stock Inflow'!$E$2:$E$601,'Stock Inflow'!$A$2:$A$601,$A4,'Stock Inflow'!$D$2:$D$601,$D4) -> 4 | H4: =SUMIFS('Stock Outflow'!$F$2:$F$601,'Stock Outflow'!$A$2:$A$601,$A4,'Stock Outflow'!$D$2:$D$601,$D4) -> 132 | I4: =SUMIFS('Stock Outflow'!$E$2:$E$601,'Stock Outflow'!$A$2:$A$601,$A4,'Stock Outflow'!$D$2:$D$601,$D4) -> 3 | J4: =E4+F4+G4-H4-I4 -> 255 | K4: =INDEX('Item Master'!$F$2:$F$51,MATCH($A4,'Item Master'!$A$2:$A$51,0)) -> 1800 | L4: =H4*K4 -> 237600 | M4: =H4/30 -> 4.4 | N4: =INDEX('Item Master'!$E$2:$E$51,MATCH($A4,'Item Master'!$A$2:$A$51,0)) -> 5 | O4: =INDEX('Product Summary'!$L$2:$L$51,MATCH($A4,'Product Summary'!$A$2:$A$51,0)) -> 11.861111 | P4: =INDEX('Product Summary'!$M$2:$M$51,MATCH($A4,'Product Summary'!$A$2:$A$51,0)) -> 36.162481 | Q4: =IF(M4=0,"",J4/M4) -> 57.954545 | R4: =IF(M4=0,"",IF(J4<=P4,0,(J4-P4)/M4)) -> 49.7358 | S4: =IF(J4<=P4,"REORDER NOW",IF(IFERROR(Q4,0)>150,"OVERSTOCK","HEALTHY")) -> HEALTHY
A5: SKU001 | B5: Wireless Earbuds Pro | C5: Audio | D5: Apr | E5: =SUMIFS('Stock Inflow'!$G$2:$G$601,'Stock Inflow'!$A$2:$A$601,$A5,'Stock Inflow'!$D$2:$D$601,$D5) -> 255 | F5: =SUMIFS('Stock Inflow'!$F$2:$F$601,'Stock Inflow'!$A$2:$A$601,$A5,'Stock Inflow'!$D$2:$D$601,$D5) -> 162 | G5: =SUMIFS('Stock Inflow'!$E$2:$E$601,'Stock Inflow'!$A$2:$A$601,$A5,'Stock Inflow'!$D$2:$D$601,$D5) -> 4 | H5: =SUMIFS('Stock Outflow'!$F$2:$F$601,'Stock Outflow'!$A$2:$A$601,$A5,'Stock Outflow'!$D$2:$D$601,$D5) -> 152 | I5: =SUMIFS('Stock Outflow'!$E$2:$E$601,'Stock Outflow'!$A$2:$A$601,$A5,'Stock Outflow'!$D$2:$D$601,$D5) -> 1 | J5: =E5+F5+G5-H5-I5 -> 268 | K5: =INDEX('Item Master'!$F$2:$F$51,MATCH($A5,'Item Master'!$A$2:$A$51,0)) -> 1800 | L5: =H5*K5 -> 273600 | M5: =H5/30 -> 5.0666667 | N5: =INDEX('Item Master'!$E$2:$E$51,MATCH($A5,'Item Master'!$A$2:$A$51,0)) -> 5 | O5: =INDEX('Product Summary'!$L$2:$L$51,MATCH($A5,'Product Summary'!$A$2:$A$51,0)) -> 11.861111 | P5: =INDEX('Product Summary'!$M$2:$M$51,MATCH($A5,'Product Summary'!$A$2:$A$51,0)) -> 36.162481 | Q5: =IF(M5=0,"",J5/M5) -> 52.894737 | R5: =IF(M5=0,"",IF(J5<=P5,0,(J5-P5)/M5)) -> 45.757405 | S5: =IF(J5<=P5,"REORDER NOW",IF(IFERROR(Q5,0)>150,"OVERSTOCK","HEALTHY")) -> HEALTHY
A6: SKU001 | B6: Wireless Earbuds Pro | C6: Audio | D6: May | E6: =SUMIFS('Stock Inflow'!$G$2:$G$601,'Stock Inflow'!$A$2:$A$601,$A6,'Stock Inflow'!$D$2:$D$601,$D6) -> 268 | F6: =SUMIFS('Stock Inflow'!$F$2:$F$601,'Stock Inflow'!$A$2:$A$601,$A6,'Stock Inflow'!$D$2:$D$601,$D6) -> 191 | G6: =SUMIFS('Stock Inflow'!$E$2:$E$601,'Stock Inflow'!$A$2:$A$601,$A6,'Stock Inflow'!$D$2:$D$601,$D6) -> 2 | H6: =SUMIFS('Stock Outflow'!$F$2:$F$601,'Stock Outflow'!$A$2:$A$601,$A6,'Stock Outflow'!$D$2:$D$601,$D6) -> 159 | I6: =SUMIFS('Stock Outflow'!$E$2:$E$601,'Stock Outflow'!$A$2:$A$601,$A6,'Stock Outflow'!$D$2:$D$601,$D6) -> 2 | J6: =E6+F6+G6-H6-I6 -> 300 | K6: =INDEX('Item Master'!$F$2:$F$51,MATCH($A6,'Item Master'!$A$2:$A$51,0)) -> 1800 | L6: =H6*K6 -> 286200 | M6: =H6/30 -> 5.3 | N6: =INDEX('Item Master'!$E$2:$E$51,MATCH($A6,'Item Master'!$A$2:$A$51,0)) -> 5 | O6: =INDEX('Product Summary'!$L$2:$L$51,MATCH($A6,'Product Summary'!$A$2:$A$51,0)) -> 11.861111 | P6: =INDEX('Product Summary'!$M$2:$M$51,MATCH($A6,'Product Summary'!$A$2:$A$51,0)) -> 36.162481 | Q6: =IF(M6=0,"",J6/M6) -> 56.603774 | R6: =IF(M6=0,"",IF(J6<=P6,0,(J6-P6)/M6)) -> 49.780664 | S6: =IF(J6<=P6,"REORDER NOW",IF(IFERROR(Q6,0)>150,"OVERSTOCK","HEALTHY")) -> HEALTHY
A7: SKU001 | B7: Wireless Earbuds Pro | C7: Audio | D7: Jun | E7: =SUMIFS('Stock Inflow'!$G$2:$G$601,'Stock Inflow'!$A$2:$A$601,$A7,'Stock Inflow'!$D$2:$D$601,$D7) -> 300 | F7: =SUMIFS('Stock Inflow'!$F$2:$F$601,'Stock Inflow'!$A$2:$A$601,$A7,'Stock Inflow'!$D$2:$D$601,$D7) -> 131 | G7: =SUMIFS('Stock Inflow'!$E$2:$E$601,'Stock Inflow'!$A$2:$A$601,$A7,'Stock Inflow'!$D$2:$D$601,$D7) -> 4 | H7: =SUMIFS('Stock Outflow'!$F$2:$F$601,'Stock Outflow'!$A$2:$A$601,$A7,'Stock Outflow'!$D$2:$D$601,$D7) -> 133 | I7: =SUMIFS('Stock Outflow'!$E$2:$E$601,'Stock Outflow'!$A$2:$A$601,$A7,'Stock Outflow'!$D$2:$D$601,$D7) -> 0 | J7: =E7+F7+G7-H7-I7 -> 302 | K7: =INDEX('Item Master'!$F$2:$F$51,MATCH($A7,'Item Master'!$A$2:$A$51,0)) -> 1800 | L7: =H7*K7 -> 239400 | M7: =H7/30 -> 4.4333333 | N7: =INDEX('Item Master'!$E$2:$E$51,MATCH($A7,'Item Master'!$A$2:$A$51,0)) -> 5 | O7: =INDEX('Product Summary'!$L$2:$L$51,MATCH($A7,'Product Summary'!$A$2:$A$51,0)) -> 11.861111 | P7: =INDEX('Product Summary'!$M$2:$M$51,MATCH($A7,'Product Summary'!$A$2:$A$51,0)) -> 36.162481 | Q7: =IF(M7=0,"",J7/M7) -> 68.120301 | R7: =IF(M7=0,"",IF(J7<=P7,0,(J7-P7)/M7)) -> 59.96335 | S7: =IF(J7<=P7,"REORDER NOW",IF(IFERROR(Q7,0)>150,"OVERSTOCK","HEALTHY")) -> HEALTHY
A8: SKU001 | B8: Wireless Earbuds Pro | C8: Audio | D8: Jul | E8: =SUMIFS('Stock Inflow'!$G$2:$G$601,'Stock Inflow'!$A$2:$A$601,$A8,'Stock Inflow'!$D$2:$D$601,$D8) -> 302 | F8: =SUMIFS('Stock Inflow'!$F$2:$F$601,'Stock Inflow'!$A$2:$A$601,$A8,'Stock Inflow'!$D$2:$D$601,$D8) -> 144 | G8: =SUMIFS('Stock Inflow'!$E$2:$E$601,'Stock Inflow'!$A$2:$A$601,$A8,'Stock Inflow'!$D$2:$D$601,$D8) -> 3 | H8: =SUMIFS('Stock Outflow'!$F$2:$F$601,'Stock Outflow'!$A$2:$A$601,$A8,'Stock Outflow'!$D$2:$D$601,$D8) -> 138 | I8: =SUMIFS('Stock Outflow'!$E$2:$E$601,'Stock Outflow'!$A$2:$A$601,$A8,'Stock Outflow'!$D$2:$D$601,$D8) -> 1 | J8: =E8+F8+G8-H8-I8 -> 310 | K8: =INDEX('Item Master'!$F$2:$F$51,MATCH($A8,'Item Master'!$A$2:$A$51,0)) -> 1800 | L8: =H8*K8 -> 248400 | M8: =H8/30 -> 4.6 | N8: =INDEX('Item Master'!$E$2:$E$51,MATCH($A8,'Item Master'!$A$2:$A$51,0)) -> 5 | O8: =INDEX('Product Summary'!$L$2:$L$51,MATCH($A8,'Product Summary'!$A$2:$A$51,0)) -> 11.861111 | P8: =INDEX('Product Summary'!$M$2:$M$51,MATCH($A8,'Product Summary'!$A$2:$A$51,0)) -> 36.162481 | Q8: =IF(M8=0,"",J8/M8) -> 67.391304 | R8: =IF(M8=0,"",IF(J8<=P8,0,(J8-P8)/M8)) -> 59.529895 | S8: =IF(J8<=P8,"REORDER NOW",IF(IFERROR(Q8,0)>150,"OVERSTOCK","HEALTHY")) -> HEALTHY
A9: SKU001 | B9: Wireless Earbuds Pro | C9: Audio | D9: Aug | E9: =SUMIFS('Stock Inflow'!$G$2:$G$601,'Stock Inflow'!$A$2:$A$601,$A9,'Stock Inflow'!$D$2:$D$601,$D9) -> 310 | F9: =SUMIFS('Stock Inflow'!$F$2:$F$601,'Stock Inflow'!$A$2:$A$601,$A9,'Stock Inflow'!$D$2:$D$601,$D9) -> 133 | G9: =SUMIFS('Stock Inflow'!$E$2:$E$601,'Stock Inflow'!$A$2:$A$601,$A9,'Stock Inflow'!$D$2:$D$601,$D9) -> 2 | H9: =SUMIFS('Stock Outflow'!$F$2:$F$601,'Stock Outflow'!$A$2:$A$601,$A9,'Stock Outflow'!$D$2:$D$601,$D9) -> 123 | I9: =SUMIFS('Stock Outflow'!$E$2:$E$601,'Stock Outflow'!$A$2:$A$601,$A9,'Stock Outflow'!$D$2:$D$601,$D9) -> 4 | J9: =E9+F9+G9-H9-I9 -> 318 | K9: =INDEX('Item Master'!$F$2:$F$51,MATCH($A9,'Item Master'!$A$2:$A$51,0)) -> 1800 | L9: =H9*K9 -> 221400 | M9: =H9/30 -> 4.1 | N9: =INDEX('Item Master'!$E$2:$E$51,MATCH($A9,'Item Master'!$A$2:$A$51,0)) -> 5 | O9: =INDEX('Product Summary'!$L$2:$L$51,MATCH($A9,'Product Summary'!$A$2:$A$51,0)) -> 11.861111 | P9: =INDEX('Product Summary'!$M$2:$M$51,MATCH($A9,'Product Summary'!$A$2:$A$51,0)) -> 36.162481 | Q9: =IF(M9=0,"",J9/M9) -> 77.560976 | R9: =IF(M9=0,"",IF(J9<=P9,0,(J9-P9)/M9)) -> 68.740858 | S9: =IF(J9<=P9,"REORDER NOW",IF(IFERROR(Q9,0)>150,"OVERSTOCK","HEALTHY")) -> HEALTHY
A10: SKU001 | B10: Wireless Earbuds Pro | C10: Audio | D10: Sep | E10: =SUMIFS('Stock Inflow'!$G$2:$G$601,'Stock Inflow'!$A$2:$A$601,$A10,'Stock Inflow'!$D$2:$D$601,$D10) -> 318 | F10: =SUMIFS('Stock Inflow'!$F$2:$F$601,'Stock Inflow'!$A$2:$A$601,$A10,'Stock Inflow'!$D$2:$D$601,$D10) -> 127 | G10: =SUMIFS('Stock Inflow'!$E$2:$E$601,'Stock Inflow'!$A$2:$A$601,$A10,'Stock Inflow'!$D$2:$D$601,$D10) -> 4 | H10: =SUMIFS('Stock Outflow'!$F$2:$F$601,'Stock Outflow'!$A$2:$A$601,$A10,'Stock Outflow'!$D$2:$D$601,$D10) -> 125 | I10: =SUMIFS('Stock Outflow'!$E$2:$E$601,'Stock Outflow'!$A$2:$A$601,$A10,'Stock Outflow'!$D$2:$D$601,$D10) -> 3 | J10: =E10+F10+G10-H10-I10 -> 321 | K10: =INDEX('Item Master'!$F$2:$F$51,MATCH($A10,'Item Master'!$A$2:$A$51,0)) -> 1800 | L10: =H10*K10 -> 225000 | M10: =H10/30 -> 4.1666667 | N10: =INDEX('Item Master'!$E$2:$E$51,MATCH($A10,'Item Master'!$A$2:$A$51,0)) -> 5 | O10: =INDEX('Product Summary'!$L$2:$L$51,MATCH($A10,'Product Summary'!$A$2:$A$51,0)) -> 11.861111 | P10: =INDEX('Product Summary'!$M$2:$M$51,MATCH($A10,'Product Summary'!$A$2:$A$51,0)) -> 36.162481 | Q10: =IF(M10=0,"",J10/M10) -> 77.04 | R10: =IF(M10=0,"",IF(J10<=P10,0,(J10-P10)/M10)) -> 68.361005 | S10: =IF(J10<=P10,"REORDER NOW",IF(IFERROR(Q10,0)>150,"OVERSTOCK","HEALTHY")) -> HEALTHY
A11: SKU001 | B11: Wireless Earbuds Pro | C11: Audio | D11: Oct | E11: =SUMIFS('Stock Inflow'!$G$2:$G$601,'Stock Inflow'!$A$2:$A$601,$A11,'Stock Inflow'!$D$2:$D$601,$D11) -> 321 | F11: =SUMIFS('Stock Inflow'!$F$2:$F$601,'Stock Inflow'!$A$2:$A$601,$A11,'Stock Inflow'!$D$2:$D$601,$D11) -> 214 | G11: =SUMIFS('Stock Inflow'!$E$2:$E$601,'Stock Inflow'!$A$2:$A$601,$A11,'Stock Inflow'!$D$2:$D$601,$D11) -> 3 | H11: =SUMIFS('Stock Outflow'!$F$2:$F$601,'Stock Outflow'!$A$2:$A$601,$A11,'Stock Outflow'!$D$2:$D$601,$D11) -> 219 | I11: =SUMIFS('Stock Outflow'!$E$2:$E$601,'Stock Outflow'!$A$2:$A$601,$A11,'Stock Outflow'!$D$2:$D$601,$D11) -> 4 | J11: =E11+F11+G11-H11-I11 -> 315 | K11: =INDEX('Item Master'!$F$2:$F$51,MATCH($A11,'Item Master'!$A$2:$A$51,0)) -> 1800 | L11: =H11*K11 -> 394200 | M11: =H11/30 -> 7.3 | N11: =INDEX('Item Master'!$E$2:$E$51,MATCH($A11,'Item Master'!$A$2:$A$51,0)) -> 5 | O11: =INDEX('Product Summary'!$L$2:$L$51,MATCH($A11,'Product Summary'!$A$2:$A$51,0)) -> 11.861111 | P11: =INDEX('Product Summary'!$M$2:$M$51,MATCH($A11,'Product Summary'!$A$2:$A$51,0)) -> 36.162481 | Q11: =IF(M11=0,"",J11/M11) -> 43.150685 | R11: =IF(M11=0,"",IF(J11<=P11,0,(J11-P11)/M11)) -> 38.19692 | S11: =IF(J11<=P11,"REORDER NOW",IF(IFERROR(Q11,0)>150,"OVERSTOCK","HEALTHY")) -> HEALTHY
A12: SKU001 | B12: Wireless Earbuds Pro | C12: Audio | D12: Nov | E12: =SUMIFS('Stock Inflow'!$G$2:$G$601,'Stock Inflow'!$A$2:$A$601,$A12,'Stock Inflow'!$D$2:$D$601,$D12) -> 315 | F12: =SUMIFS('Stock Inflow'!$F$2:$F$601,'Stock Inflow'!$A$2:$A$601,$A12,'Stock Inflow'!$D$2:$D$601,$D12) -> 230 | G12: =SUMIFS('Stock Inflow'!$E$2:$E$601,'Stock Inflow'!$A$2:$A$601,$A12,'Stock Inflow'!$D$2:$D$601,$D12) -> 6 | H12: =SUMIFS('Stock Outflow'!$F$2:$F$601,'Stock Outflow'!$A$2:$A$601,$A12,'Stock Outflow'!$D$2:$D$601,$D12) -> 178 | I12: =SUMIFS('Stock Outflow'!$E$2:$E$601,'Stock Outflow'!$A$2:$A$601,$A12,'Stock Outflow'!$D$2:$D$601,$D12) -> 6 | J12: =E12+F12+G12-H12-I12 -> 367 | K12: =INDEX('Item Master'!$F$2:$F$51,MATCH($A12,'Item Master'!$A$2:$A$51,0)) -> 1800 | L12: =H12*K12 -> 320400 | M12: =H12/30 -> 5.9333333 | N12: =INDEX('Item Master'!$E$2:$E$51,MATCH($A12,'Item Master'!$A$2:$A$51,0)) -> 5 | O12: =INDEX('Product Summary'!$L$2:$L$51,MATCH($A12,'Product Summary'!$A$2:$A$51,0)) -> 11.861111 | P12: =INDEX('Product Summary'!$M$2:$M$51,MATCH($A12,'Product Summary'!$A$2:$A$51,0)) -> 36.162481 | Q12: =IF(M12=0,"",J12/M12) -> 61.853933 | R12: =IF(M12=0,"",IF(J12<=P12,0,(J12-P12)/M12)) -> 55.759132 | S12: =IF(J12<=P12,"REORDER NOW",IF(IFERROR(Q12,0)>150,"OVERSTOCK","HEALTHY")) -> HEALTHY
A13: SKU001 | B13: Wireless Earbuds Pro | C13: Audio | D13: Dec | E13: =SUMIFS('Stock Inflow'!$G$2:$G$601,'Stock Inflow'!$A$2:$A$601,$A13,'Stock Inflow'!$D$2:$D$601,$D13) -> 367 | F13: =SUMIFS('Stock Inflow'!$F$2:$F$601,'Stock Inflow'!$A$2:$A$601,$A13,'Stock Inflow'!$D$2:$D$601,$D13) -> 149 | G13: =SUMIFS('Stock Inflow'!$E$2:$E$601,'Stock Inflow'!$A$2:$A$601,$A13,'Stock Inflow'!$D$2:$D$601,$D13) -> 5 | H13: =SUMIFS('Stock Outflow'!$F$2:$F$601,'Stock Outflow'!$A$2:$A$601,$A13,'Stock Outflow'!$D$2:$D$601,$D13) -> 138 | I13: =SUMIFS('Stock Outflow'!$E$2:$E$601,'Stock Outflow'!$A$2:$A$601,$A13,'Stock Outflow'!$D$2:$D$601,$D13) -> 1 | J13: =E13+F13+G13-H13-I13 -> 382 | K13: =INDEX('Item Master'!$F$2:$F$51,MATCH($A13,'Item Master'!$A$2:$A$51,0)) -> 1800 | L13: =H13*K13 -> 248400 | M13: =H13/30 -> 4.6 | N13: =INDEX('Item Master'!$E$2:$E$51,MATCH($A13,'Item Master'!$A$2:$A$51,0)) -> 5 | O13: =INDEX('Product Summary'!$L$2:$L$51,MATCH($A13,'Product Summary'!$A$2:$A$51,0)) -> 11.861111 | P13: =INDEX('Product Summary'!$M$2:$M$51,MATCH($A13,'Product Summary'!$A$2:$A$51,0)) -> 36.162481 | Q13: =IF(M13=0,"",J13/M13) -> 83.043478 | R13: =IF(M13=0,"",IF(J13<=P13,0,(J13-P13)/M13)) -> 75.182069 | S13: =IF(J13<=P13,"REORDER NOW",IF(IFERROR(Q13,0)>150,"OVERSTOCK","HEALTHY")) -> HEALTHY
... A601: SKU050 | B601: Anti-Theft Phone Pouch | C601: Accessories | D601: Dec | E601: =SUMIFS('Stock Inflow'!$G$2:$G$601,'Stock Inflow'!$A$2:$A$601,$A601,'Stock Inflow'!$D$2:$D$601,$D601) -> 418 | F601: =SUMIFS('Stock Inflow'!$F$2:$F$601,'Stock Inflow'!$A$2:$A$601,$A601,'Stock Inflow'!$D$2:$D$601,$D601) -> 20 | G601: =SUMIFS('Stock Inflow'!$E$2:$E$601,'Stock Inflow'!$A$2:$A$601,$A601,'Stock Inflow'!$D$2:$D$601,$D601) -> 1 | H601: =SUMIFS('Stock Outflow'!$F$2:$F$601,'Stock Outflow'!$A$2:$A$601,$A601,'Stock Outflow'!$D$2:$D$601,$D601) -> 18 | I601: =SUMIFS('Stock Outflow'!$E$2:$E$601,'Stock Outflow'!$A$2:$A$601,$A601,'Stock Outflow'!$D$2:$D$601,$D601) -> 1 | J601: =E601+F601+G601-H601-I601 -> 420 | K601: =INDEX('Item Master'!$F$2:$F$51,MATCH($A601,'Item Master'!$A$2:$A$51,0)) -> 180 | L601: =H601*K601 -> 3240 | M601: =H601/30 -> 0.6 | N601: =INDEX('Item Master'!$E$2:$E$51,MATCH($A601,'Item Master'!$A$2:$A$51,0)) -> 7 | O601: =INDEX('Product Summary'!$L$2:$L$51,MATCH($A601,'Product Summary'!$A$2:$A$51,0)) -> 1.3416667 | P601: =INDEX('Product Summary'!$M$2:$M$51,MATCH($A601,'Product Summary'!$A$2:$A$51,0)) -> 5.7718037 | Q601: =IF(M601=0,"",J601/M601) -> 700 | R601: =IF(M601=0,"",IF(J601<=P601,0,(J601-P601)/M601)) -> 690.38033 | S601: =IF(J601<=P601,"REORDER NOW",IF(IFERROR(Q601,0)>150,"OVERSTOCK","HEALTHY")) -> OVERSTOCK

Sheet Product Summary
A1: Product ID | B1: Product Name | C1: Category | D1: Total Sales (Units) | E1: Total Cost (Rs) | F1: Avg Daily Usage (Annual) | G1: Max Monthly Sales | H1: Avg Monthly Sales | I1: StDev Monthly Sales | J1: CV (%) | K1: Lead Time (Days) | L1: Safety Stock | M1: Reorder Level | N1: Ordering Cost (Rs) | O1: Holding Cost per Unit (Rs) | P1: EOQ (Units) | Q1: Order Cycle Time (Days) | R1: Orders per Year | S1: Opening Stock (Jan) | T1: Closing Stock (Dec) | U1: Average Inventory (Units) | V1: Average Inventory Value (Rs) | W1: Turnover Ratio | X1: Days Inventory on Hand | Y1: ABC Value (Rs) | Z1: Cumulative % of Value | AA1: ABC Class | AB1: Reviewing Frequency | AC1: Current Stock (Latest) | AD1: Current Status
A2: SKU001 | B2: Wireless Earbuds Pro | C2: Audio | D2: =SUM(Sales!$E$2:$E$13) -> 1774 | E2: =D2*INDEX('Item Master'!$F$2:$F$51,MATCH($A2,'Item Master'!$A$2:$A$51,0)) -> 3193200 | F2: =D2/365 -> 4.860274 | G2: =MAX(Sales!$E$2:$E$13) -> 219 | H2: =AVERAGE(Sales!$E$2:$E$13) -> 147.83333 | I2: =STDEV(Sales!$E$2:$E$13) -> 27.265807 | J2: =IFERROR(I2/H2,0) -> 0.18443613 | K2: =INDEX('Item Master'!$E$2:$E$51,MATCH($A2,'Item Master'!$A$2:$A$51,0)) -> 5 | L2: =((G2-H2)/30)*K2 -> 11.861111 | M2: =(F2*K2)+L2 -> 36.162481 | N2: =INDEX('Item Master'!$G$2:$G$51,MATCH($A2,'Item Master'!$A$2:$A$51,0)) -> 500 | O2: =INDEX('Item Master'!$H$2:$H$51,MATCH($A2,'Item Master'!$A$2:$A$51,0)) -> 360 | P2: =IFERROR(SQRT((2*D2*N2)/O2),0) -> 70.198132 | Q2: =IFERROR(P2/F2,0) -> 14.443246 | R2: =IFERROR(D2/P2,0) -> 25.271328 | S2: =Calculations!$E$2 -> 220 | T2: =Calculations!$J$13 -> 382 | U2: =(S2+T2)/2 -> 301 | V2: =U2*INDEX('Item Master'!$F$2:$F$51,MATCH($A2,'Item Master'!$A$2:$A$51,0)) -> 541800 | W2: =IFERROR(E2/V2,0) -> 5.8936877 | X2: =IFERROR(365/W2,0) -> 61.930665 | Y2: =E2 -> 3193200 | Z2: =SUMIF($Y$2:$Y$51,">="&Y2,$Y$2:$Y$51)/SUM($Y$2:$Y$51) -> 0.47371331 | AA2: =IF(Z2<=0.8,"A",IF(Z2<=0.95,"B","C")) -> A | AB2: =IF(AA2="A","Weekly",IF(AA2="B","Monthly","Quarterly")) -> Weekly | AC2: =T2 -> 382 | AD2: =IF(AC2<=M2,"REORDER NOW",IF(IFERROR(AC2/F2,0)>150,"OVERSTOCK","HEALTHY")) -> HEALTHY
A3: SKU002 | B3: Bluetooth Speaker Mini | C3: Audio | D3: =SUM(Sales!$E$14:$E$25) -> 2199 | E3: =D3*INDEX('Item Master'!$F$2:$F$51,MATCH($A3,'Item Master'!$A$2:$A$51,0)) -> 2638800 | F3: =D3/365 -> 6.0246575 | G3: =MAX(Sales!$E$14:$E$25) -> 286 | H3: =AVERAGE(Sales!$E$14:$E$25) -> 183.25 | I3: =STDEV(Sales!$E$14:$E$25) -> 34.404347 | J3: =IFERROR(I3/H3,0) -> 0.18774541 | K3: =INDEX('Item Master'!$E$2:$E$51,MATCH($A3,'Item Master'!$A$2:$A$51,0)) -> 3 | L3: =((G3-H3)/30)*K3 -> 10.275 | M3: =(F3*K3)+L3 -> 28.348973 | N3: =INDEX('Item Master'!$G$2:$G$51,MATCH($A3,'Item Master'!$A$2:$A$51,0)) -> 500 | O3: =INDEX('Item Master'!$H$2:$H$51,MATCH($A3,'Item Master'!$A$2:$A$51,0)) -> 240 | P3: =IFERROR(SQRT((2*D3*N3)/O3),0) -> 95.720949 | Q3: =IFERROR(P3/F3,0) -> 15.888197 | R3: =IFERROR(D3/P3,0) -> 22.973028 | S3: =Calculations!$E$14 -> 216 | T3: =Calculations!$J$25 -> 427 | U3: =(S3+T3)/2 -> 321.5 | V3: =U3*INDEX('Item Master'!$F$2:$F$51,MATCH($A3,'Item Master'!$A$2:$A$51,0)) -> 385800 | W3: =IFERROR(E3/V3,0) -> 6.8398134 | X3: =IFERROR(365/W3,0) -> 53.364029 | Y3: =E3 -> 2638800 | Z3: =SUMIF($Y$2:$Y$51,">="&Y3,$Y$2:$Y$51)/SUM($Y$2:$Y$51) -> 0.54933686 | AA3: =IF(Z3<=0.8,"A",IF(Z3<=0.95,"B","C")) -> A | AB3: =IF(AA3="A","Weekly",IF(AA3="B","Monthly","Quarterly")) -> Weekly | AC3: =T3 -> 427 | AD3: =IF(AC3<=M3,"REORDER NOW",IF(IFERROR(AC3/F3,0)>150,"OVERSTOCK","HEALTHY")) -> HEALTHY
A4: SKU003 | B4: Bluetooth Speaker XL | C4: Audio | D4: =SUM(Sales!$E$26:$E$37) -> 2815 | E4: =D4*INDEX('Item Master'!$F$2:$F$51,MATCH($A4,'Item Master'!$A$2:$A$51,0)) -> 6193000 | F4: =D4/365 -> 7.7123288 | G4: =MAX(Sales!$E$26:$E$37) -> 377 | H4: =AVERAGE(Sales!$E$26:$E$37) -> 234.58333 | I4: =STDEV(Sales!$E$26:$E$37) -> 51.092533 | J4: =IFERROR(I4/H4,0) -> 0.21780121 | K4: =INDEX('Item Master'!$E$2:$E$51,MATCH($A4,'Item Master'!$A$2:$A$51,0)) -> 5 | L4: =((G4-H4)/30)*K4 -> 23.736111 | M4: =(F4*K4)+L4 -> 62.297755 | N4: =INDEX('Item Master'!$G$2:$G$51,MATCH($A4,'Item Master'!$A$2:$A$51,0)) -> 500 | O4: =INDEX('Item Master'!$H$2:$H$51,MATCH($A4,'Item Master'!$A$2:$A$51,0)) -> 440 | P4: =IFERROR(SQRT((2*D4*N4)/O4),0) -> 79.985794 | Q4: =IFERROR(P4/F4,0) -> 10.37116 | R4: =IFERROR(D4/P4,0) -> 35.193749 | S4: =Calculations!$E$26 -> 216 | T4: =Calculations!$J$37 -> 529 | U4: =(S4+T4)/2 -> 372.5 | V4: =U4*INDEX('Item Master'!$F$2:$F$51,MATCH($A4,'Item Master'!$A$2:$A$51,0)) -> 819500 | W4: =IFERROR(E4/V4,0) -> 7.557047 | X4: =IFERROR(365/W4,0) -> 48.29929 | Y4: =E4 -> 6193000 | Z4: =SUMIF($Y$2:$Y$51,">="&Y4,$Y$2:$Y$51)/SUM($Y$2:$Y$51) -> 0.38220158 | AA4: =IF(Z4<=0.8,"A",IF(Z4<=0.95,"B","C")) -> A | AB4: =IF(AA4="A","Weekly",IF(AA4="B","Monthly","Quarterly")) -> Weekly | AC4: =T4 -> 529 | AD4: =IF(AC4<=M4,"REORDER NOW",IF(IFERROR(AC4/F4,0)>150,"OVERSTOCK","HEALTHY")) -> HEALTHY
A5: SKU004 | B5: Wired Earphones Basic | C5: Audio | D5: =SUM(Sales!$E$38:$E$49) -> 2454 | E5: =D5*INDEX('Item Master'!$F$2:$F$51,MATCH($A5,'Item Master'!$A$2:$A$51,0)) -> 368100 | F5: =D5/365 -> 6.7232877 | G5: =MAX(Sales!$E$38:$E$49) -> 285 | H5: =AVERAGE(Sales!$E$38:$E$49) -> 204.5 | I5: =STDEV(Sales!$E$38:$E$49) -> 32.831526 | J5: =IFERROR(I5/H5,0) -> 0.16054536 | K5: =INDEX('Item Master'!$E$2:$E$51,MATCH($A5,'Item Master'!$A$2:$A$51,0)) -> 14 | L5: =((G5-H5)/30)*K5 -> 37.566667 | M5: =(F5*K5)+L5 -> 131.69269 | N5: =INDEX('Item Master'!$G$2:$G$51,MATCH($A5,'Item Master'!$A$2:$A$51,0)) -> 500 | O5: =INDEX('Item Master'!$H$2:$H$51,MATCH($A5,'Item Master'!$A$2:$A$51,0)) -> 30 | P5: =IFERROR(SQRT((2*D5*N5)/O5),0) -> 286.00699 | Q5: =IFERROR(P5/F5,0) -> 42.539752 | R5: =IFERROR(D5/P5,0) -> 8.5802098 | S5: =Calculations!$E$38 -> 141 | T5: =Calculations!$J$49 -> 237 | U5: =(S5+T5)/2 -> 189 | V5: =U5*INDEX('Item Master'!$F$2:$F$51,MATCH($A5,'Item Master'!$A$2:$A$51,0)) -> 28350 | W5: =IFERROR(E5/V5,0) -> 12.984127 | X5: =IFERROR(365/W5,0) -> 28.111247 | Y5: =E5 -> 368100 | Z5: =SUMIF($Y$2:$Y$51,">="&Y5,$Y$2:$Y$51)/SUM($Y$2:$Y$51) -> 0.82333899 | AA5: =IF(Z5<=0.8,"A",IF(Z5<=0.95,"B","C")) -> B | AB5: =IF(AA5="A","Weekly",IF(AA5="B","Monthly","Quarterly")) -> Monthly | AC5: =T5 -> 237 | AD5: =IF(AC5<=M5,"REORDER NOW",IF(IFERROR(AC5/F5,0)>150,"OVERSTOCK","HEALTHY")) -> HEALTHY
A6: SKU005 | B6: Noise Cancelling Headphones | C6: Audio | D6: =SUM(Sales!$E$50:$E$61) -> 2041 | E6: =D6*INDEX('Item Master'!$F$2:$F$51,MATCH($A6,'Item Master'!$A$2:$A$51,0)) -> 7143500 | F6: =D6/365 -> 5.5917808 | G6: =MAX(Sales!$E$50:$E$61) -> 251 | H6: =AVERAGE(Sales!$E$50:$E$61) -> 170.08333 | I6: =STDEV(Sales!$E$50:$E$61) -> 28.497076 | J6: =IFERROR(I6/H6,0) -> 0.16754773 | K6: =INDEX('Item Master'!$E$2:$E$51,MATCH($A6,'Item Master'!$A$2:$A$51,0)) -> 7 | L6: =((G6-H6)/30)*K6 -> 18.880556 | M6: =(F6*K6)+L6 -> 58.023021 | N6: =INDEX('Item Master'!$G$2:$G$51,MATCH($A6,'Item Master'!$A$2:$A$51,0)) -> 500 | O6: =INDEX('Item Master'!$H$2:$H$51,MATCH($A6,'Item Master'!$A$2:$A$51,0)) -> 700 | P6: =IFERROR(SQRT((2*D6*N6)/O6),0) -> 53.997354 | Q6: =IFERROR(P6/F6,0) -> 9.6565578 | R6: =IFERROR(D6/P6,0) -> 37.798148 | S6: =Calculations!$E$50 -> 288 | T6: =Calculations!$J$61 -> 561 | U6: =(S6+T6)/2 -> 424.5 | V6: =U6*INDEX('Item Master'!$F$2:$F$51,MATCH($A6,'Item Master'!$A$2:$A$51,0)) -> 1485750 | W6: =IFERROR(E6/V6,0) -> 4.8080094 | X6: =IFERROR(365/W6,0) -> 75.914993 | Y6: =E6 -> 7143500 | Z6: =SUMIF($Y$2:$Y$51,">="&Y6,$Y$2:$Y$51)/SUM($Y$2:$Y$51) -> 0.20472065 | AA6: =IF(Z6<=0.8,"A",IF(Z6<=0.95,"B","C")) -> A | AB6: =IF(AA6="A","Weekly",IF(AA6="B","Monthly","Quarterly")) -> Weekly | AC6: =T6 -> 561 | AD6: =IF(AC6<=M6,"REORDER NOW",IF(IFERROR(AC6/F6,0)>150,"OVERSTOCK","HEALTHY")) -> HEALTHY
A7: SKU006 | B7: USB-C Charging Cable 1m | C7: Cables | D7: =SUM(Sales!$E$62:$E$73) -> 1754 | E7: =D7*INDEX('Item Master'!$F$2:$F$51,MATCH($A7,'Item Master'!$A$2:$A$51,0)) -> 157860 | F7: =D7/365 -> 4.8054795 | G7: =MAX(Sales!$E$62:$E$73) -> 195 | H7: =AVERAGE(Sales!$E$62:$E$73) -> 146.16667 | I7: =STDEV(Sales!$E$62:$E$73) -> 18.99681 | J7: =IFERROR(I7/H7,0) -> 0.12996677 | K7: =INDEX('Item Master'!$E$2:$E$51,MATCH($A7,'Item Master'!$A$2:$A$51,0)) -> 5 | L7: =((G7-H7)/30)*K7 -> 8.1388889 | M7: =(F7*K7)+L7 -> 32.166286 | N7: =INDEX('Item Master'!$G$2:$G$51,MATCH($A7,'Item Master'!$A$2:$A$51,0)) -> 500 | O7: =INDEX('Item Master'!$H$2:$H$51,MATCH($A7,'Item Master'!$A$2:$A$51,0)) -> 18 | P7: =IFERROR(SQRT((2*D7*N7)/O7),0) -> 312.16093 | Q7: =IFERROR(P7/F7,0) -> 64.959372 | R7: =IFERROR(D7/P7,0) -> 5.6188967 | S7: =Calculations!$E$62 -> 314 | T7: =Calculations!$J$73 -> 482 | U7: =(S7+T7)/2 -> 398 | V7: =U7*INDEX('Item Master'!$F$2:$F$51,MATCH($A7,'Item Master'!$A$2:$A$51,0)) -> 35820 | W7: =IFERROR(E7/V7,0) -> 4.4070352 | X7: =IFERROR(365/W7,0) -> 82.822121 | Y7: =E7 -> 157860 | Z7: =SUMIF($Y$2:$Y$51,">="&Y7,$Y$2:$Y$51)/SUM($Y$2:$Y$51) -> 0.95688128 | AA7: =IF(Z7<=0.8,"A",IF(Z7<=0.95,"B","C")) -> C | AB7: =IF(AA7="A","Weekly",IF(AA7="B","Monthly","Quarterly")) -> Quarterly | AC7: =T7 -> 482 | AD7: =IF(AC7<=M7,"REORDER NOW",IF(IFERROR(AC7/F7,0)>150,"OVERSTOCK","HEALTHY")) -> HEALTHY
A8: SKU007 | B8: USB-C Charging Cable 2m | C8: Cables | D8: =SUM(Sales!$E$74:$E$85) -> 2410 | E8: =D8*INDEX('Item Master'!$F$2:$F$51,MATCH($A8,'Item Master'!$A$2:$A$51,0)) -> 313300 | F8: =D8/365 -> 6.6027397 | G8: =MAX(Sales!$E$74:$E$85) -> 328 | H8: =AVERAGE(Sales!$E$74:$E$85) -> 200.83333 | I8: =STDEV(Sales!$E$74:$E$85) -> 42.486005 | J8: =IFERROR(I8/H8,0) -> 0.21154857 | K8: =INDEX('Item Master'!$E$2:$E$51,MATCH($A8,'Item Master'!$A$2:$A$51,0)) -> 5 | L8: =((G8-H8)/30)*K8 -> 21.194444 | M8: =(F8*K8)+L8 -> 54.208143 | N8: =INDEX('Item Master'!$G$2:$G$51,MATCH($A8,'Item Master'!$A$2:$A$51,0)) -> 500 | O8: =INDEX('Item Master'!$H$2:$H$51,MATCH($A8,'Item Master'!$A$2:$A$51,0)) -> 26 | P8: =IFERROR(SQRT((2*D8*N8)/O8),0) -> 304.45411 | Q8: =IFERROR(P8/F8,0) -> 46.11027 | R8: =IFERROR(D8/P8,0) -> 7.915807 | S8: =Calculations!$E$74 -> 378 | T8: =Calculations!$J$85 -> 710 | U8: =(S8+T8)/2 -> 544 | V8: =U8*INDEX('Item Master'!$F$2:$F$51,MATCH($A8,'Item Master'!$A$2:$A$51,0)) -> 70720 | W8: =IFERROR(E8/V8,0) -> 4.4301471 | X8: =IFERROR(365/W8,0) -> 82.390041 | Y8: =E8 -> 313300 | Z8: =SUMIF($Y$2:$Y$51,">="&Y8,$Y$2:$Y$51)/SUM($Y$2:$Y$51) -> 0.87145629 | AA8: =IF(Z8<=0.8,"A",IF(Z8<=0.95,"B","C")) -> B | AB8: =IF(AA8="A","Weekly",IF(AA8="B","Monthly","Quarterly")) -> Monthly | AC8: =T8 -> 710 | AD8: =IF(AC8<=M8,"REORDER NOW",IF(IFERROR(AC8/F8,0)>150,"OVERSTOCK","HEALTHY")) -> HEALTHY
A9: SKU008 | B9: Lightning Cable 1m | C9: Cables | D9: =SUM(Sales!$E$86:$E$97) -> 1849 | E9: =D9*INDEX('Item Master'!$F$2:$F$51,MATCH($A9,'Item Master'!$A$2:$A$51,0)) -> 277350 | F9: =D9/365 -> 5.0657534 | G9: =MAX(Sales!$E$86:$E$97) -> 246 | H9: =AVERAGE(Sales!$E$86:$E$97) -> 154.08333 | I9: =STDEV(Sales!$E$86:$E$97) -> 32.759338 | J9: =IFERROR(I9/H9,0) -> 0.21260793 | K9: =INDEX('Item Master'!$E$2:$E$51,MATCH($A9,'Item Master'!$A$2:$A$51,0)) -> 3 | L9: =((G9-H9)/30)*K9 -> 9.1916667 | M9: =(F9*K9)+L9 -> 24.388927 | N9: =INDEX('Item Master'!$G$2:$G$51,MATCH($A9,'Item Master'!$A$2:$A$51,0)) -> 500 | O9: =INDEX('Item Master'!$H$2:$H$51,MATCH($A9,'Item Master'!$A$2:$A$51,0)) -> 30 | P9: =IFERROR(SQRT((2*D9*N9)/O9),0) -> 248.26062 | Q9: =IFERROR(P9/F9,0) -> 49.007639 | R9: =IFERROR(D9/P9,0) -> 7.4478185 | S9: =Calculations!$E$86 -> 139 | T9: =Calculations!$J$97 -> 271 | U9: =(S9+T9)/2 -> 205 | V9: =U9*INDEX('Item Master'!$F$2:$F$51,MATCH($A9,'Item Master'!$A$2:$A$51,0)) -> 30750 | W9: =IFERROR(E9/V9,0) -> 9.0195122 | X9: =IFERROR(365/W9,0) -> 40.46782 | Y9: =E9 -> 277350 | Z9: =SUMIF($Y$2:$Y$51,">="&Y9,$Y$2:$Y$51)/SUM($Y$2:$Y$51) -> 0.87940468 | AA9: =IF(Z9<=0.8,"A",IF(Z9<=0.95,"B","C")) -> B | AB9: =IF(AA9="A","Weekly",IF(AA9="B","Monthly","Quarterly")) -> Monthly | AC9: =T9 -> 271 | AD9: =IF(AC9<=M9,"REORDER NOW",IF(IFERROR(AC9/F9,0)>150,"OVERSTOCK","HEALTHY")) -> HEALTHY
A10: SKU009 | B10: Micro USB Cable | C10: Cables | D10: =SUM(Sales!$E$98:$E$109) -> 2582 | E10: =D10*INDEX('Item Master'!$F$2:$F$51,MATCH($A10,'Item Master'!$A$2:$A$51,0)) -> 154920 | F10: =D10/365 -> 7.0739726 | G10: =MAX(Sales!$E$98:$E$109) -> 326 | H10: =AVERAGE(Sales!$E$98:$E$109) -> 215.16667 | I10: =STDEV(Sales!$E$98:$E$109) -> 41.060561 | J10: =IFERROR(I10/H10,0) -> 0.19083142 | K10: =INDEX('Item Master'!$E$2:$E$51,MATCH($A10,'Item Master'!$A$2:$A$51,0)) -> 14 | L10: =((G10-H10)/30)*K10 -> 51.722222 | M10: =(F10*K10)+L10 -> 150.75784 | N10: =INDEX('Item Master'!$G$2:$G$51,MATCH($A10,'Item Master'!$A$2:$A$51,0)) -> 500 | O10: =INDEX('Item Master'!$H$2:$H$51,MATCH($A10,'Item Master'!$A$2:$A$51,0)) -> 12 | P10: =IFERROR(SQRT((2*D10*N10)/O10),0) -> 463.86061 | Q10: =IFERROR(P10/F10,0) -> 65.572859 | R10: =IFERROR(D10/P10,0) -> 5.5663273 | S10: =Calculations!$E$98 -> 166 | T10: =Calculations!$J$109 -> 451 | U10: =(S10+T10)/2 -> 308.5 | V10: =U10*INDEX('Item Master'!$F$2:$F$51,MATCH($A10,'Item Master'!$A$2:$A$51,0)) -> 18510 | W10: =IFERROR(E10/V10,0) -> 8.36953 | X10: =IFERROR(365/W10,0) -> 43.610573 | Y10: =E10 -> 154920 | Z10: =SUMIF($Y$2:$Y$51,">="&Y10,$Y$2:$Y$51)/SUM($Y$2:$Y$51) -> 0.97025095 | AA10: =IF(Z10<=0.8,"A",IF(Z10<=0.95,"B","C")) -> C | AB10: =IF(AA10="A","Weekly",IF(AA10="B","Monthly","Quarterly")) -> Quarterly | AC10: =T10 -> 451 | AD10: =IF(AC10<=M10,"REORDER NOW",IF(IFERROR(AC10/F10,0)>150,"OVERSTOCK","HEALTHY")) -> HEALTHY
A11: SKU010 | B11: HDMI Cable 2m | C11: Cables | D11: =SUM(Sales!$E$110:$E$121) -> 2281 | E11: =D11*INDEX('Item Master'!$F$2:$F$51,MATCH($A11,'Item Master'!$A$2:$A$51,0)) -> 456200 | F11: =D11/365 -> 6.2493151 | G11: =MAX(Sales!$E$110:$E$121) -> 271 | H11: =AVERAGE(Sales!$E$110:$E$121) -> 190.08333 | I11: =STDEV(Sales!$E$110:$E$121) -> 32.864621 | J11: =IFERROR(I11/H11,0) -> 0.17289586 | K11: =INDEX('Item Master'!$E$2:$E$51,MATCH($A11,'Item Master'!$A$2:$A$51,0)) -> 7 | L11: =((G11-H11)/30)*K11 -> 18.880556 | M11: =(F11*K11)+L11 -> 62.625761 | N11: =INDEX('Item Master'!$G$2:$G$51,MATCH($A11,'Item Master'!$A$2:$A$51,0)) -> 500 | O11: =INDEX('Item Master'!$H$2:$H$51,MATCH($A11,'Item Master'!$A$2:$A$51,0)) -> 40 | P11: =IFERROR(SQRT((2*D11*N11)/O11),0) -> 238.79908 | Q11: =IFERROR(P11/F11,0) -> 38.21204 | R11: =IFERROR(D11/P11,0) -> 9.5519631 | S11: =Calculations!$E$110 -> 346 | T11: =Calculations!$J$121 -> 614 | U11: =(S11+T11)/2 -> 480 | V11: =U11*INDEX('Item Master'!$F$2:$F$51,MATCH($A11,'Item Master'!$A$2:$A$51,0)) -> 96000 | W11: =IFERROR(E11/V11,0) -> 4.7520833 | X11: =IFERROR(365/W11,0) -> 76.808417 | Y11: =E11 -> 456200 | Z11: =SUMIF($Y$2:$Y$51,">="&Y11,$Y$2:$Y$51)/SUM($Y$2:$Y$51) -> 0.79119582 | AA11: =IF(Z11<=0.8,"A",IF(Z11<=0.95,"B","C")) -> A | AB11: =IF(AA11="A","Weekly",IF(AA11="B","Monthly","Quarterly")) -> Weekly | AC11: =T11 -> 614 | AD11: =IF(AC11<=M11,"REORDER NOW",IF(IFERROR(AC11/F11,0)>150,"OVERSTOCK","HEALTHY")) -> HEALTHY
A12: SKU011 | B12: 20W Fast Charger Adapter | C12: Chargers | D12: =SUM(Sales!$E$122:$E$133) -> 864 | E12: =D12*INDEX('Item Master'!$F$2:$F$51,MATCH($A12,'Item Master'!$A$2:$A$51,0)) -> 345600 | F12: =D12/365 -> 2.3671233 | G12: =MAX(Sales!$E$122:$E$133) -> 121 | H12: =AVERAGE(Sales!$E$122:$E$133) -> 72 | I12: =STDEV(Sales!$E$122:$E$133) -> 17.606817 | J12: =IFERROR(I12/H12,0) -> 0.24453912 | K12: =INDEX('Item Master'!$E$2:$E$51,MATCH($A12,'Item Master'!$A$2:$A$51,0)) -> 10 | L12: =((G12-H12)/30)*K12 -> 16.333333 | M12: =(F12*K12)+L12 -> 40.004566 | N12: =INDEX('Item Master'!$G$2:$G$51,MATCH($A12,'Item Master'!$A$2:$A$51,0)) -> 500 | O12: =INDEX('Item Master'!$H$2:$H$51,MATCH($A12,'Item Master'!$A$2:$A$51,0)) -> 80 | P12: =IFERROR(SQRT((2*D12*N12)/O12),0) -> 103.92305 | Q12: =IFERROR(P12/F12,0) -> 43.902677 | R12: =IFERROR(D12/P12,0) -> 8.3138439 | S12: =Calculations!$E$122 -> 316 | T12: =Calculations!$J$133 -> 418 | U12: =(S12+T12)/2 -> 367 | V12: =U12*INDEX('Item Master'!$F$2:$F$51,MATCH($A12,'Item Master'!$A$2:$A$51,0)) -> 146800 | W12: =IFERROR(E12/V12,0) -> 2.3542234 | X12: =IFERROR(365/W12,0) -> 155.04051 | Y12: =E12 -> 345600 | Z12: =SUMIF($Y$2:$Y$51,">="&Y12,$Y$2:$Y$51)/SUM($Y$2:$Y$51) -> 0.84358465 | AA12: =IF(Z12<=0.8,"A",IF(Z12<=0.95,"B","C")) -> B | AB12: =IF(AA12="A","Weekly",IF(AA12="B","Monthly","Quarterly")) -> Monthly | AC12: =T12 -> 418 | AD12: =IF(AC12<=M12,"REORDER NOW",IF(IFERROR(AC12/F12,0)>150,"OVERSTOCK","HEALTHY")) -> OVERSTOCK
A13: SKU012 | B13: 65W GaN Charger | C13: Chargers | D13: =SUM(Sales!$E$134:$E$145) -> 1604 | E13: =D13*INDEX('Item Master'!$F$2:$F$51,MATCH($A13,'Item Master'!$A$2:$A$51,0)) -> 1764400 | F13: =D13/365 -> 4.3945205 | G13: =MAX(Sales!$E$134:$E$145) -> 217 | H13: =AVERAGE(Sales!$E$134:$E$145) -> 133.66667 | I13: =STDEV(Sales!$E$134:$E$145) -> 29.812546 | J13: =IFERROR(I13/H13,0) -> 0.2230365 | K13: =INDEX('Item Master'!$E$2:$E$51,MATCH($A13,'Item Master'!$A$2:$A$51,0)) -> 5 | L13: =((G13-H13)/30)*K13 -> 13.888889 | M13: =(F13*K13)+L13 -> 35.861492 | N13: =INDEX('Item Master'!$G$2:$G$51,MATCH($A13,'Item Master'!$A$2:$A$51,0)) -> 500 | O13: =INDEX('Item Master'!$H$2:$H$51,MATCH($A13,'Item Master'!$A$2:$A$51,0)) -> 220 | P13: =IFERROR(SQRT((2*D13*N13)/O13),0) -> 85.38682 | Q13: =IFERROR(P13/F13,0) -> 19.430293 | R13: =IFERROR(D13/P13,0) -> 18.7851 | S13: =Calculations!$E$134 -> 101 | T13: =Calculations!$J$145 -> 304 | U13: =(S13+T13)/2 -> 202.5 | V13: =U13*INDEX('Item Master'!$F$2:$F$51,MATCH($A13,'Item Master'!$A$2:$A$51,0)) -> 222750 | W13: =IFERROR(E13/V13,0) -> 7.9209877 | X13: =IFERROR(365/W13,0) -> 46.080112 | Y13: =E13 -> 1764400 | Z13: =SUMIF($Y$2:$Y$51,">="&Y13,$Y$2:$Y$51)/SUM($Y$2:$Y$51) -> 0.59990159 | AA13: =IF(Z13<=0.8,"A",IF(Z13<=0.95,"B","C")) -> A | AB13: =IF(AA13="A","Weekly",IF(AA13="B","Monthly","Quarterly")) -> Weekly | AC13: =T13 -> 304 | AD13: =IF(AC13<=M13,"REORDER NOW",IF(IFERROR(AC13/F13,0)>150,"OVERSTOCK","HEALTHY")) -> HEALTHY
A14: SKU013 | B14: Wireless Charging Pad | C14: Chargers | D14: =SUM(Sales!$E$146:$E$157) -> 755 | E14: =D14*INDEX('Item Master'!$F$2:$F$51,MATCH($A14,'Item Master'!$A$2:$A$51,0)) -> 528500 | F14: =D14/365 -> 2.0684932 | G14: =MAX(Sales!$E$146:$E$157) -> 97 | H14: =AVERAGE(Sales!$E$146:$E$157) -> 62.916667 | I14: =STDEV(Sales!$E$146:$E$157) -> 11.950339 | J14: =IFERROR(I14/H14,0) -> 0.18993917 | K14: =INDEX('Item Master'!$E$2:$E$51,MATCH($A14,'Item Master'!$A$2:$A$51,0)) -> 5 | L14: =((G14-H14)/30)*K14 -> 5.6805556 | M14: =(F14*K14)+L14 -> 16.023021 | N14: =INDEX('Item Master'!$G$2:$G$51,MATCH($A14,'Item Master'!$A$2:$A$51,0)) -> 500 | O14: =INDEX('Item Master'!$H$2:$H$51,MATCH($A14,'Item Master'!$A$2:$A$51,0)) -> 140 | P14: =IFERROR(SQRT((2*D14*N14)/O14),0) -> 73.436075 | Q14: =IFERROR(P14/F14,0) -> 35.502209 | R14: =IFERROR(D14/P14,0) -> 10.281051 | S14: =Calculations!$E$146 -> 230 | T14: =Calculations!$J$157 -> 326 | U14: =(S14+T14)/2 -> 278 | V14: =U14*INDEX('Item Master'!$F$2:$F$51,MATCH($A14,'Item Master'!$A$2:$A$51,0)) -> 194600 | W14: =IFERROR(E14/V14,0) -> 2.7158273 | X14: =IFERROR(365/W14,0) -> 134.39735 | Y14: =E14 -> 528500 | Z14: =SUMIF($Y$2:$Y$51,">="&Y14,$Y$2:$Y$51)/SUM($Y$2:$Y$51) -> 0.7781219 | AA14: =IF(Z14<=0.8,"A",IF(Z14<=0.95,"B","C")) -> A | AB14: =IF(AA14="A","Weekly",IF(AA14="B","Monthly","Quarterly")) -> Weekly | AC14: =T14 -> 326 | AD14: =IF(AC14<=M14,"REORDER NOW",IF(IFERROR(AC14/F14,0)>150,"OVERSTOCK","HEALTHY")) -> OVERSTOCK
A15: SKU014 | B15: Car Charger Dual Port | C15: Chargers | D15: =SUM(Sales!$E$158:$E$169) -> 861 | E15: =D15*INDEX('Item Master'!$F$2:$F$51,MATCH($A15,'Item Master'!$A$2:$A$51,0)) -> 215250 | F15: =D15/365 -> 2.3589041 | G15: =MAX(Sales!$E$158:$E$169) -> 113 | H15: =AVERAGE(Sales!$E$158:$E$169) -> 71.75 | I15: =STDEV(Sales!$E$158:$E$169) -> 14.691525 | J15: =IFERROR(I15/H15,0) -> 0.20475993 | K15: =INDEX('Item Master'!$E$2:$E$51,MATCH($A15,'Item Master'!$A$2:$A$51,0)) -> 5 | L15: =((G15-H15)/30)*K15 -> 6.875 | M15: =(F15*K15)+L15 -> 18.669521 | N15: =INDEX('Item Master'!$G$2:$G$51,MATCH($A15,'Item Master'!$A$2:$A$51,0)) -> 500 | O15: =INDEX('Item Master'!$H$2:$H$51,MATCH($A15,'Item Master'!$A$2:$A$51,0)) -> 50 | P15: =IFERROR(SQRT((2*D15*N15)/O15),0) -> 131.225 | Q15: =IFERROR(P15/F15,0) -> 55.629645 | R15: =IFERROR(D15/P15,0) -> 6.5612499 | S15: =Calculations!$E$158 -> 156 | T15: =Calculations!$J$169 -> 232 | U15: =(S15+T15)/2 -> 194 | V15: =U15*INDEX('Item Master'!$F$2:$F$51,MATCH($A15,'Item Master'!$A$2:$A$51,0)) -> 48500 | W15: =IFERROR(E15/V15,0) -> 4.4381443 | X15: =IFERROR(365/W15,0) -> 82.24158 | Y15: =E15 -> 215250 | Z15: =SUMIF($Y$2:$Y$51,">="&Y15,$Y$2:$Y$51)/SUM($Y$2:$Y$51) -> 0.92635845 | AA15: =IF(Z15<=0.8,"A",IF(Z15<=0.95,"B","C")) -> B | AB15: =IF(AA15="A","Weekly",IF(AA15="B","Monthly","Quarterly")) -> Monthly | AC15: =T15 -> 232 | AD15: =IF(AC15<=M15,"REORDER NOW",IF(IFERROR(AC15/F15,0)>150,"OVERSTOCK","HEALTHY")) -> HEALTHY
A16: SKU015 | B16: Power Bank 10000mAh | C16: Power Banks | D16: =SUM(Sales!$E$170:$E$181) -> 1363 | E16: =D16*INDEX('Item Master'!$F$2:$F$51,MATCH($A16,'Item Master'!$A$2:$A$51,0)) -> 1226700 | F16: =D16/365 -> 3.7342466 | G16: =MAX(Sales!$E$170:$E$181) -> 165 | H16: =AVERAGE(Sales!$E$170:$E$181) -> 113.58333 | I16: =STDEV(Sales!$E$170:$E$181) -> 18.012412 | J16: =IFERROR(I16/H16,0) -> 0.15858323 | K16: =INDEX('Item Master'!$E$2:$E$51,MATCH($A16,'Item Master'!$A$2:$A$51,0)) -> 3 | L16: =((G16-H16)/30)*K16 -> 5.1416667 | M16: =(F16*K16)+L16 -> 16.344406 | N16: =INDEX('Item Master'!$G$2:$G$51,MATCH($A16,'Item Master'!$A$2:$A$51,0)) -> 500 | O16: =INDEX('Item Master'!$H$2:$H$51,MATCH($A16,'Item Master'!$A$2:$A$51,0)) -> 180 | P16: =IFERROR(SQRT((2*D16*N16)/O16),0) -> 87.018517 | Q16: =IFERROR(P16/F16,0) -> 23.302831 | R16: =IFERROR(D16/P16,0) -> 15.663333 | S16: =Calculations!$E$170 -> 143 | T16: =Calculations!$J$181 -> 282 | U16: =(S16+T16)/2 -> 212.5 | V16: =U16*INDEX('Item Master'!$F$2:$F$51,MATCH($A16,'Item Master'!$A$2:$A$51,0)) -> 191250 | W16: =IFERROR(E16/V16,0) -> 6.4141176 | X16: =IFERROR(365/W16,0) -> 56.905723 | Y16: =E16 -> 1226700 | Z16: =SUMIF($Y$2:$Y$51,">="&Y16,$Y$2:$Y$51)/SUM($Y$2:$Y$51) -> 0.67537898 | AA16: =IF(Z16<=0.8,"A",IF(Z16<=0.95,"B","C")) -> A | AB16: =IF(AA16="A","Weekly",IF(AA16="B","Monthly","Quarterly")) -> Weekly | AC16: =T16 -> 282 | AD16: =IF(AC16<=M16,"REORDER NOW",IF(IFERROR(AC16/F16,0)>150,"OVERSTOCK","HEALTHY")) -> HEALTHY
